Traceback (most recent call last):
  File "/n/home00/sumedh/spmax_sae/experiments/expt19_separability_diffmag2/trainmodel.py", line 270, in <module>
    train_loss_epoch[t] = train(batchdataloader, model, optimizer, \
  File "/n/home00/sumedh/spmax_sae/experiments/expt19_separability_diffmag2/../../functions/train_test.py", line 43, in train
    pred, xlatent = model(X, return_hidden=True)
  File "/n/holylabs/LABS/ba_lab/Users/sumedh/conda/envs/spmax/lib/python3.10/site-packages/torch/nn/modules/module.py", line 1553, in _wrapped_call_impl
    return self._call_impl(*args, **kwargs)
  File "/n/holylabs/LABS/ba_lab/Users/sumedh/conda/envs/spmax/lib/python3.10/site-packages/torch/nn/modules/module.py", line 1562, in _call_impl
    return forward_call(*args, **kwargs)
  File "/n/home00/sumedh/spmax_sae/experiments/expt19_separability_diffmag2/../../models.py", line 118, in forward
    raise ValueError('Invalid sae_type')
ValueError: Invalid sae_type